---------------------------------
[2025-05-20 14:07:14][INFO][200]:La conexion [dbconn_standard] esta desabilitada en el archivo .config
---------------------------------
[2025-05-20 14:07:14][INFO][200]:Iniciando ...
---------------------------------
[2025-05-20 14:07:19][EXCEPTION][500]:PYTHON-EXCEPTION:

>>>>>>>>>>>>>>>[TRACEBACK]<<<<<<<<<<<<<<<

  File "/home/crowdcounting/sophie/pinos-analytics-cv/src/IOT-Agent/main.py", line 10, in <module>
    ProjectDirector.go( sys.argv )
  File "/home/crowdcounting/sophie/pinos-analytics-cv/src/IOT-Agent/System/Director/ProjectDirector.py", line 133, in go
    ProjectDirector().setFlux( argv )
  File "/home/crowdcounting/sophie/pinos-analytics-cv/src/IOT-Agent/System/Director/ProjectDirector.py", line 113, in setFlux
    self.__play(
  File "/home/crowdcounting/sophie/pinos-analytics-cv/src/IOT-Agent/System/Director/ProjectDirector.py", line 56, in __play
    yolov11_warmup(model=self.model, repetitions=10, verbose=False)
    ^^^^^^^^^^^^^^

>>>>>>>>>>>>>>[ERROR_DESC]<<<<<<<<<<<<<<<

  [NameError]:name 'yolov11_warmup' is not defined

>>>>>>>>>>>>>>>>>>>><<<<<<<<<<<<<<<<<<<<<

